scripts/test_case11.txt
40
0 o
1 o
2 o
3 o
4 o
5 o
6 o
7 o
8 o
9 o
10 o
11 o
12 o
13 o
14 o
15 o
16 o
17 o
18 o
19 o
20 o
21 o
22 o
23 o
24 o
25 o
26 o
27 o
28 o
29 o
30 o
31 o
32 o
33 o
34 o
35 o
36 o
37 o
38 o
39 o
.
38 B 48725141 GOOG 15699 9226
39 B 2570247 MSFT 49993 8197
39 B 57634522 AAPL 95342 443
35 S 5638523 AAPL 16580 9720
36 B 48439215 GOOG 79427 4974
38 B 29148692 GOOG 78794 1646
39 S 42260327 AMZN 30654 6991
39 B 53303033 AMZN 41987 303
39 B 37546120 MSFT 43232 9296
39 C 37546120
39 C 42260327
39 S 51392716 AMZN 23981 2176
39 S 7025085 AMZN 4539 1788
38 S 5326226 MSFT 88926 6247
39 B 39540408 MSFT 88787 7934
39 C 37546120
39 S 81958864 MSFT 27354 4925
38 C 29148692
39 C 2570247
39 B 31867502 GOOG 25483 8898
33 B 5373086 GOOG 26704 2834
39 S 61125049 AAPL 49882 6269
37 S 2789186 GOOG 93900 4053
35 C 5638523
39 C 51392716
39 B 11743657 GOOG 68606 6663
37 C 2789186
31 S 72768081 MSFT 82990 9446
37 S 45793889 AMZN 7873 9341
38 C 48725141
39 S 53631953 MSFT 66872 5929
36 B 82184780 GOOG 48236 4082
38 B 39733262 AMZN 17605 4344
39 B 95481926 MSFT 64627 457
38 S 27926024 GOOG 29542 5060
38 S 38176895 GOOG 58241 9697
39 C 81958864
37 B 18527639 GOOG 76799 3576
37 C 18527639
37 S 45321808 GOOG 5619 1842
38 B 73936015 AAPL 40852 9416
38 B 55160027 MSFT 79589 1338
39 C 53631953
39 B 61391499 AMZN 22622 5442
38 B 10134693 AMZN 95426 6606
37 B 53275505 AMZN 78587 1972
39 S 99560441 AAPL 40062 4321
37 S 40471744 MSFT 29543 3472
38 S 93828552 MSFT 38781 6742
39 S 19640147 GOOG 19590 3414
39 C 37546120
35 S 83756832 AAPL 38897 1112
37 C 2789186
37 S 5725007 MSFT 82666 5217
36 S 95183614 MSFT 69592 1824
38 B 87362945 MSFT 24876 4146
33 B 94245608 MSFT 60481 4749
38 S 23434268 AMZN 92952 2714
38 S 19756193 AAPL 69381 6236
39 C 61125049
38 B 51173049 GOOG 32133 8606
39 S 32788609 GOOG 6427 7824
39 S 70764307 AAPL 43062 4866
39 S 81897521 MSFT 49075 7065
39 C 2570247
38 C 87362945
38 B 71688933 AAPL 78762 1855
35 S 64458053 MSFT 98902 6895
39 C 7025085
36 B 17316504 AMZN 15354 489
39 S 96587219 AMZN 66625 9330
37 C 18527639
39 S 66745935 GOOG 58919 7015
39 C 19640147
39 S 62411489 GOOG 91285 3247
36 B 94663395 AAPL 67224 7040
39 S 8574399 GOOG 48359 1589
39 S 27823638 AAPL 4775 8141
39 B 33966160 AAPL 91868 2266
39 B 71195140 MSFT 18237 6248
38 S 69268829 MSFT 75867 6424
38 C 29148692
39 C 53631953
36 S 26702127 GOOG 46254 3687
39 B 31605120 MSFT 42220 2000
39 S 1516310 MSFT 34980 4942
39 B 48924786 MSFT 53371 280
39 C 61125049
39 S 99090987 MSFT 57033 3280
38 C 29148692
39 C 61391499
39 S 85580309 GOOG 68952 166
35 S 82483979 AAPL 33184 586
38 C 27926024
39 B 33034584 MSFT 49984 6925
37 S 37420806 AMZN 28233 1786
39 S 24615977 MSFT 31746 9413
39 C 81897521
38 S 50748193 GOOG 12441 1889
39 S 89596315 AMZN 87095 2328
39 B 69459396 AMZN 89598 8940
38 S 22265989 MSFT 25768 5955
39 B 96633945 AMZN 44011 711
37 S 41548023 GOOG 90442 4061
39 B 99661388 GOOG 5523 3712
39 C 69459396
39 S 39804160 GOOG 39555 5663
39 C 11743657
39 C 53303033
39 B 96168856 GOOG 88943 2264
33 S 84049343 GOOG 98854 319
39 B 66056604 MSFT 3273 2786
39 S 40821595 GOOG 76717 9835
39 S 86322846 AAPL 26080 1883
39 B 50485448 MSFT 27993 7873
37 B 93085420 AMZN 72146 3237
39 S 47973098 AMZN 98116 6516
39 S 49596167 AAPL 74747 7333
38 S 30027892 MSFT 50796 3464
38 C 27926024
38 B 79913113 MSFT 87107 3027
39 S 98552207 MSFT 90364 4783
39 C 85580309
39 C 47973098
39 S 91994387 MSFT 78530 9794
31 C 72768081
36 S 51335727 AAPL 7763 5194
36 S 14264930 AAPL 94491 8924
38 B 8861279 AAPL 51807 2690
38 S 50798857 GOOG 55431 5499
36 C 51335727
34 B 15203504 AAPL 47155 7154
38 C 29148692
39 B 47857804 AMZN 83395 8584
38 S 1800866 AAPL 85638 7694
38 C 55160027
36 B 87305869 GOOG 21186 6275
32 B 90940611 MSFT 15520 533
39 B 78395906 GOOG 36671 9417
38 C 22265989
39 C 27823638
39 C 31867502
38 B 58161899 MSFT 86223 1699
38 C 23434268
39 B 93013157 AMZN 4499 849
39 S 2388782 AAPL 94189 6827
39 C 2388782
39 S 12583670 AAPL 11602 2779
37 S 41266097 AAPL 10640 7500
39 S 79214154 AMZN 2973 275
39 C 99560441
38 S 54123609 MSFT 29111 2338
39 B 87906593 GOOG 74421 1452
39 B 6762152 AMZN 92182 7793
39 C 61391499
39 C 99560441
38 S 95417283 AAPL 45331 8714
39 S 84105332 GOOG 67347 2042
38 S 37751813 GOOG 8847 8654
39 C 91994387
38 B 78400070 AMZN 37693 4641
39 B 79949533 AMZN 94423 4692
39 S 46069260 MSFT 96955 1149
38 C 54123609
38 B 24983755 AMZN 94648 2002
38 S 59864527 AMZN 27283 5299
36 B 59113324 MSFT 27379 9167
39 S 39336942 MSFT 3549 7596
38 C 51173049
39 S 59684751 AAPL 35740 5734
39 B 93108094 MSFT 70557 2878
39 C 70764307
39 C 39336942
39 C 81897521
39 C 93108094
38 S 62022542 GOOG 28396 859
39 C 79214154
37 C 18527639
37 C 53275505
36 C 51335727
38 B 88392186 GOOG 1049 8451
37 C 40471744
32 S 3532758 AAPL 37421 1667
39 C 7025085
38 B 55865052 AMZN 75958 4077
38 B 72483087 GOOG 25938 571
38 S 45428679 MSFT 71886 7908
38 C 5326226
39 S 33504325 GOOG 28099 7797
39 B 78863526 AMZN 62696 8571
38 C 8861279
39 B 63458453 GOOG 99704 8310
39 B 37907732 MSFT 47357 3238
38 S 14691962 MSFT 90706 9199
37 S 59720693 GOOG 79161 8356
37 C 53275505
37 C 2789186
38 S 3975547 AAPL 39856 4941
38 C 88392186
37 S 76803924 GOOG 24997 4662
38 C 3975547
38 B 43071853 GOOG 28066 8067
36 B 81666823 MSFT 10502 8109
38 S 48143740 GOOG 93284 1324
37 B 10381425 MSFT 27858 5193
38 C 30027892
33 S 8646032 GOOG 43256 1785
38 S 49661357 MSFT 49368 3505
37 B 52544250 AAPL 12293 6473
37 C 18527639
38 C 43071853
37 B 95535507 AAPL 63564 9343
36 S 3597387 AMZN 68948 3402
38 C 48725141
38 C 22265989
37 B 43199237 GOOG 23514 3659
38 B 36516938 MSFT 26387 1791
38 S 65885885 MSFT 37897 2995
38 C 51173049
33 S 96239220 AAPL 82519 8377
38 B 1022704 MSFT 74297 9626
37 B 91360764 AMZN 47154 1309
38 S 10129578 GOOG 62142 4687
35 C 5638523
37 B 64788223 AMZN 54826 2584
36 B 30266674 GOOG 61133 3452
38 B 42557651 MSFT 18489 2145
38 C 54123609
33 S 18359369 MSFT 35179 606
37 B 85989686 AAPL 80409 8658
36 S 394894 GOOG 37188 9368
38 S 49346943 GOOG 77509 3745
37 B 89034056 GOOG 99395 5766
38 B 65817187 AAPL 32082 7770
36 B 60282531 MSFT 53724 6005
36 C 82184780
38 S 71429778 MSFT 53764 4914
38 S 96869627 MSFT 46747 677
37 C 41266097
36 B 76639865 AMZN 17040 4233
38 B 11408156 MSFT 17566 2307
38 C 54123609
38 B 86186282 GOOG 86348 8302
38 C 71688933
36 B 35594391 AMZN 54539 6279
38 C 42557651
38 C 42557651
38 C 48725141
35 C 5638523
37 B 32248269 MSFT 84050 83
36 C 394894
38 S 95198692 AAPL 15804 738
37 C 89034056
38 S 90499412 MSFT 65739 5160
36 C 82184780
38 B 35180822 AAPL 55842 2608
36 S 88346865 AMZN 58142 9055
37 S 85424753 AAPL 41324 2610
38 S 49042802 AMZN 69207 4665
38 C 10129578
38 C 39733262
37 C 10381425
37 B 15025624 AAPL 38425 3948
37 C 53275505
37 C 18527639
34 C 15203504
38 C 10134693
38 C 8861279
36 C 3597387
36 S 56993769 AAPL 77092 1986
38 S 12270867 AAPL 49895 6321
38 S 30066672 AMZN 93527 9427
38 C 54123609
35 B 56656689 AMZN 17224 2005
36 S 16544661 GOOG 66215 7473
38 S 24045655 MSFT 12902 8560
38 B 27558361 GOOG 5950 5924
38 S 71061975 AAPL 94571 4190
35 C 5638523
38 C 49346943
38 S 90480027 AMZN 13574 6746
37 C 64788223
38 S 37256240 GOOG 48536 3985
38 C 71061975
38 S 80473758 AAPL 2735 3645
37 C 93085420
38 C 23434268
36 S 52596449 AMZN 81892 9545
38 C 43071853
34 C 15203504
37 C 93085420
37 S 25549832 GOOG 33438 685
37 B 68676081 MSFT 40347 6169
35 S 21324566 AMZN 40960 8792
37 C 43199237
37 B 23925608 GOOG 7448 5362
36 C 56993769
37 B 75012051 AAPL 13143 3088
33 S 10778396 AAPL 89368 8325
35 B 28276487 GOOG 42135 1303
37 S 78804827 GOOG 5263 5682
37 B 93538267 GOOG 30261 1652
35 B 80696866 AMZN 68183 5795
37 B 24945070 MSFT 32085 2999
33 C 94245608
37 C 59720693
37 C 23925608
36 B 48722864 MSFT 68337 4471
36 C 17316504
37 S 47323383 AAPL 29824 9744
36 S 37627777 MSFT 62181 9299
36 S 40348479 MSFT 67171 5295
36 B 17885171 GOOG 21847 7660
37 C 76803924
36 C 82184780
32 S 64835835 GOOG 56096 2258
35 C 64458053
33 C 18359369
37 C 93085420
37 B 15512482 GOOG 25204 8388
37 C 43199237
37 C 23925608
36 S 46672560 GOOG 5997 2167
34 C 15203504
33 B 47846441 AAPL 58983 2278
