scripts/test_case12.txt
40
0 o
1 o
2 o
3 o
4 o
5 o
6 o
7 o
8 o
9 o
10 o
11 o
12 o
13 o
14 o
15 o
16 o
17 o
18 o
19 o
20 o
21 o
22 o
23 o
24 o
25 o
26 o
27 o
28 o
29 o
30 o
31 o
32 o
33 o
34 o
35 o
36 o
37 o
38 o
39 o
.
37 S 55352277 AMZN 30931 8445
36 B 31279355 GOOG 38226 2083
38 B 36274146 AMZN 4256 3584
38 C 36274146
39 S 5273194 GOOG 45033 2587
39 S 89546853 AAPL 7937 7249
39 C 5273194
37 S 80122166 AAPL 20434 3445
38 B 52073576 MSFT 90955 1204
37 S 50491989 GOOG 24751 9973
39 S 16498696 GOOG 27182 4866
39 S 70555904 AAPL 92236 2518
39 B 21778058 AMZN 77755 6632
38 B 16703499 AAPL 7181 6677
38 B 4649076 AMZN 18037 1387
39 S 32029567 MSFT 8951 9999
39 C 89546853
37 S 83506498 MSFT 63913 2182
38 C 16703499
39 B 57954201 GOOG 64290 2588
39 B 85216839 AMZN 61069 3618
36 B 88203381 GOOG 43733 8713
39 S 55947031 GOOG 20935 4596
38 B 71173549 GOOG 7342 4938
39 C 32029567
39 S 88919254 AMZN 18715 1562
37 S 17955539 GOOG 29211 7222
39 C 5273194
39 C 32029567
39 C 21778058
39 B 16857155 AAPL 65282 1673
39 C 16498696
39 S 77078041 AAPL 67730 683
35 B 38787859 AMZN 36501 318
39 S 39463059 GOOG 68693 4612
38 S 53850077 AMZN 49708 2937
39 B 43602174 AMZN 46804 3171
38 S 61043500 AAPL 82422 9764
36 C 88203381
39 C 21778058
39 B 26957752 AAPL 88580 819
39 C 39463059
38 B 27271349 AMZN 92221 4054
38 B 46412848 AAPL 41805 251
38 B 65563586 AAPL 68910 8708
38 S 44590021 AAPL 96242 6891
39 C 39463059
39 S 79742670 MSFT 46453 8343
38 C 65563586
38 B 11524209 MSFT 29918 6851
39 C 32029567
38 B 9979024 AAPL 96543 1870
35 B 12269967 AMZN 6663 8126
29 S 35360083 GOOG 18760 8651
36 C 31279355
39 B 48023718 AAPL 78577 3620
39 B 80772425 GOOG 70798 2891
35 S 478020 MSFT 18824 6899
39 C 5273194
39 C 48023718
38 C 36274146
38 B 94512954 AMZN 38040 4308
39 B 44766191 AAPL 60087 5132
37 C 55352277
37 B 21124733 AMZN 40785 7122
32 S 93613068 AMZN 94850 3073
39 S 20089614 GOOG 76696 9120
35 B 59773634 MSFT 8226 698
39 B 55649363 GOOG 23311 9273
39 S 16251811 AAPL 73601 6024
36 C 88203381
39 S 21019121 AAPL 30948 1645
39 S 73789780 AAPL 1202 4058
37 S 4397533 MSFT 40010 4438
38 S 8060851 AAPL 69405 1686
39 B 50183675 GOOG 36276 334
36 C 31279355
39 C 16251811
39 B 35169660 GOOG 26452 9796
38 S 75782707 AMZN 93571 9528
39 B 54179570 GOOG 87626 6247
38 C 8060851
39 C 73789780
35 B 62740624 GOOG 94929 8103
39 S 7729964 MSFT 84242 8146
39 C 89546853
38 B 35246709 MSFT 21756 6490
38 B 10017777 AAPL 80814 1186
39 C 89546853
38 C 8060851
37 S 43163366 MSFT 38882 141
37 B 98252087 AAPL 11537 4824
39 B 98910779 MSFT 66240 6315
38 B 64657629 AMZN 72447 2776
38 C 4649076
39 C 21778058
37 C 98252087
36 B 69881651 MSFT 59076 1048
38 C 27271349
39 S 66253392 AAPL 75732 3663
39 B 53626881 MSFT 89275 6472
39 S 6641976 AMZN 94157 4751
35 B 86799191 AAPL 33019 6031
39 C 39463059
38 C 8060851
37 C 17955539
39 B 91493604 AMZN 80783 8330
39 S 14516387 MSFT 93622 2117
38 C 27271349
39 C 98910779
39 S 98133521 GOOG 57959 9127
39 B 70725941 AMZN 2917 2539
39 C 77078041
37 C 98252087
37 B 62453782 AAPL 44476 6818
39 C 73789780
38 C 46412848
39 S 75226336 GOOG 59722 6817
39 B 86419154 AAPL 74903 712
38 B 86402176 GOOG 34024 2865
38 S 51182778 AAPL 5697 3842
34 S 6085195 AAPL 69248 4717
34 S 91288797 GOOG 12668 4829
38 C 27271349
39 C 7729964
37 B 34414934 GOOG 46986 7617
39 S 35420947 AMZN 70702 6013
38 B 75988762 AAPL 35683 7135
38 C 11524209
39 S 75425332 MSFT 40643 384
39 B 25098955 MSFT 38026 4605
38 S 83030483 GOOG 63337 8575
37 S 77530077 AMZN 64104 9274
38 B 42263620 GOOG 69660 7600
36 B 67984435 AAPL 94674 5354
37 B 72870767 MSFT 7378 7238
39 S 47893352 GOOG 44974 3043
39 B 66208655 MSFT 92705 3576
39 C 75226336
39 S 261633 GOOG 84815 2692
38 C 53850077
38 C 10017777
39 B 57883512 GOOG 61412 9118
30 B 94784954 MSFT 31314 6942
39 B 53889597 MSFT 87374 6265
39 S 56778650 GOOG 15928 4720
38 B 82747431 AAPL 6821 5459
36 C 67984435
39 B 51539693 AMZN 29926 5576
39 B 53193510 MSFT 82270 5294
38 B 85355049 AAPL 72213 6289
39 C 53193510
36 C 88203381
38 B 61593123 MSFT 59354 6021
36 S 95584845 MSFT 11716 4567
35 B 33818959 GOOG 90377 9430
33 S 24035920 AAPL 74337 6251
39 B 22645795 GOOG 32449 9287
37 C 80122166
38 S 23210974 MSFT 6479 5292
39 S 77921840 MSFT 53946 2885
39 S 29191267 AAPL 43455 150
37 C 77530077
39 S 23170340 GOOG 59338 928
39 C 53626881
38 S 77507997 MSFT 90659 3266
39 S 69209299 AMZN 66689 3936
38 C 52073576
39 C 91493604
37 C 77530077
37 S 51585071 AMZN 44292 9078
37 C 83506498
38 C 61043500
37 B 79441326 MSFT 61918 1308
39 B 713409 GOOG 37851 6672
38 S 53266597 AMZN 45883 4560
39 B 99769386 AAPL 43451 4774
39 S 66139675 MSFT 84106 1887
36 B 96010234 GOOG 94903 688
37 S 25662983 AAPL 79878 4213
39 C 54179570
36 C 95584845
39 C 261633
39 C 50183675
39 S 25156431 AAPL 97353 7175
39 S 85456887 AMZN 77393 3949
38 S 36095249 AAPL 43235 1946
39 S 83109826 MSFT 56357 8988
39 C 55947031
38 C 53850077
38 B 84876893 AAPL 60499 8016
39 S 94933235 MSFT 33699 1449
36 C 69881651
39 S 33174374 AAPL 90117 8123
39 B 23338070 GOOG 30245 7822
39 C 43602174
37 B 93382333 AAPL 21636 4083
36 C 96010234
39 S 56500324 AAPL 56488 5177
39 S 85955270 GOOG 1699 4279
38 C 36274146
38 B 4632964 AAPL 56237 6763
37 S 679180 GOOG 76003 784
36 C 88203381
39 B 63191236 MSFT 52789 6770
37 B 23385162 GOOG 53564 1091
39 C 75425332
39 C 57883512
38 C 35246709
36 C 31279355
36 C 69881651
32 B 22273442 AAPL 80532 9244
36 B 33050216 MSFT 73513 8392
37 C 50491989
38 S 31735666 MSFT 27378 3976
38 S 55230056 AMZN 91521 3936
35 B 49225463 AAPL 36477 9714
37 S 44548616 AMZN 60554 6326
38 C 75988762
38 B 55884190 AAPL 71213 3471
38 B 37311754 AAPL 38632 8520
38 C 75988762
38 C 52073576
38 B 21090188 GOOG 97545 2887
35 B 77824254 AMZN 76468 4183
38 C 10017777
36 C 69881651
38 C 9979024
36 B 51341231 AAPL 43258 7654
38 S 43525590 AAPL 91080 4375
36 S 19921498 GOOG 53583 4384
35 C 12269967
37 S 28282933 GOOG 13076 4504
38 B 77655135 GOOG 53807 33
38 S 98249193 MSFT 86030 5058
34 C 91288797
34 B 3561415 MSFT 16073 634
33 S 4157618 AMZN 83019 7953
38 C 52073576
36 C 51341231
35 B 31603487 GOOG 13526 186
36 C 51341231
36 S 2401711 GOOG 2819 2636
37 S 29658425 AAPL 21458 2889
38 C 77507997
35 B 45971535 AAPL 27044 6617
36 S 55645529 MSFT 81176 2274
38 B 91002268 MSFT 78406 80
35 B 12211040 MSFT 71153 2464
36 C 51341231
37 B 87201238 MSFT 57112 1224
37 C 17955539
36 B 93056162 AAPL 86663 8786
37 C 23385162
38 B 92655619 MSFT 82231 5072
36 C 33050216
29 C 35360083
38 S 58718459 MSFT 76099 8662
38 B 4679829 AAPL 50792 3395
36 C 2401711
36 C 88203381
37 B 60617375 GOOG 33539 7146
38 C 84876893
35 C 33818959
37 C 28282933
38 C 77655135
38 S 19650401 MSFT 57762 177
38 B 62154718 MSFT 59956 4214
37 S 51801824 AMZN 3874 3382
38 B 38978549 MSFT 38489 343
38 B 18022436 AAPL 52472 1042
38 B 56118010 AMZN 60819 2886
35 S 96542385 MSFT 81205 6686
37 S 59284233 AAPL 91239 5328
38 B 78948563 AAPL 75876 4036
38 S 39084546 GOOG 14435 1182
38 C 42263620
38 C 9979024
37 B 2438521 MSFT 78780 4264
37 S 93400894 AMZN 93664 1245
38 S 23760 AAPL 56856 5544
38 S 17061841 MSFT 20645 2809
38 S 26521569 GOOG 89609 810
37 S 637226 MSFT 92915 9953
38 S 42741828 GOOG 42295 16
34 B 96020889 AMZN 68696 9642
37 S 6510055 AMZN 60972 568
38 S 28415965 AAPL 47957 253
37 S 95817741 AMZN 18077 5478
38 C 36095249
36 S 52256132 MSFT 91173 5169
38 B 11020581 GOOG 3804 7286
35 S 18454674 AMZN 28501 6802
36 C 93056162
38 S 24315479 GOOG 73200 7992
33 C 4157618
38 S 47056639 AAPL 31150 7343
37 C 95817741
37 C 25662983
36 S 30410823 MSFT 78995 1875
38 C 38978549
36 B 80231557 AMZN 85848 3250
37 C 21124733
38 B 54966962 GOOG 7825 4554
36 B 54012027 GOOG 41782 2544
38 B 5927991 AAPL 87574 9444
38 B 1655561 AMZN 58890 1768
37 B 93624017 AMZN 97016 3146
38 B 53167623 MSFT 87535 6732
38 C 8060851
36 C 51341231
38 B 61880350 GOOG 86643 2295
38 C 43525590
34 S 24529307 AAPL 68015 7552
36 B 81113760 MSFT 50691 7982
35 C 62740624
37 B 18400053 AMZN 97679 2469
37 S 93627719 GOOG 14107 6666
36 B 71981820 GOOG 25016 5194
35 B 18101332 GOOG 3576 8746
35 B 39164956 AAPL 77762 5927
34 C 3561415
36 C 51341231
35 S 74975787 AMZN 45324 2441
